4:36:46:dig2:Warn:DEBUG MODE ON. Can be slow !
4:36:47:alg:Info:analyze ./programs/hola/32.dig.c
4:36:47:alg:Info:set seed to: 1493804206.5 (test 48)
4:36:47:alg:Info:check reachability
4:36:47:alg:Info:gen eqts at 1 locs: l19 (int i, int j, int k, int b, int n)
Traceback (most recent call last):
  File "dig2.py", line 71, in <module>
    doEqts=not args.noeqts, doIeqs=not args.noieqs)
  File "/home/tnguyen/Dropbox/git/dig2/alg.py", line 406, in start
    if doEqts: _gen('eqts')
  File "/home/tnguyen/Dropbox/git/dig2/alg.py", line 399, in _gen
    invs = solver.gen(deg, traces, inps)
  File "/home/tnguyen/Dropbox/git/dig2/alg.py", line 193, in gen
    initrs = [self.getInitTraces(loc, deg, traces, inps) for loc in traces]
  File "/home/tnguyen/Dropbox/git/dig2/alg.py", line 123, in getInitTraces
    newTraces = self.getTracesAndUpdate(newInps, traces)
  File "/home/tnguyen/Dropbox/git/dig2/alg.py", line 68, in getTracesAndUpdate
    assert inps
AssertionError
