4:57:55:dig2:Warn:DEBUG MODE ON. Can be slow !
4:57:56:alg:Info:analyze ./programs/hola/38.dig.c
4:57:56:alg:Info:set seed to: 1493805475.7 (test 47)
4:57:56:alg:Info:check reachability
4:57:56:alg:Info:gen eqts at 1 locs: l15 (int i, int x, int y)
4:58:5:alg:Info:2 invs:
l15: (x*x) - 4*x*y + 4*(y*y) - x + 2*y == 0, i - x == 0
4:58:5:alg:Info:gen ieqs at 1 locs: l15 (int i, int x, int y)
4:58:5:alg:Info:1 locs: check upperbounds for 18 terms
Traceback (most recent call last):
  File "dig2.py", line 71, in <module>
    doEqts=not args.noeqts, doIeqs=not args.noieqs)
  File "/home/tnguyen/Dropbox/git/dig2/alg.py", line 407, in start
    if doIeqs: _gen('ieqs')        
  File "/home/tnguyen/Dropbox/git/dig2/alg.py", line 399, in _gen
    invs = solver.gen(deg, traces, inps)
  File "/home/tnguyen/Dropbox/git/dig2/alg.py", line 252, in gen
    _ = self.getTracesAndUpdate(newInps, traces)
  File "/home/tnguyen/Dropbox/git/dig2/alg.py", line 68, in getTracesAndUpdate
    assert inps
AssertionError
